# 错误处理

**错误处理（Error handling）** 是响应错误以及从错误中恢复的过程。`Swift` 在运行时提供了抛出、捕获、传递和操作可恢复错误（recoverable errors）的一等支持（first-class support）。

## 1. 表示错误(Error)

在Swift中, 错误使用实现 `Error` 协议的类型(可以是枚举，类，结构体)的值来表示，这个空协议表明该类型可以用于错误处理。


```swift
enum VendingMachineError: Error {
    case invalidSelection                     //选择无效
    case insufficientFunds(coinsNeeded: Int) //金额不足
    case outOfStock                             //缺货
}
```

## 2. 抛出错误

Swift 使用 `throw` 关键字抛出错误。

```swift
throw VendingMachineError.insufficientFunds(coinsNeeded: 5)
```

## 3. 处理错误

某个错误被抛出时，附近的某部分代码必须负责处理这个错误。

`Swift`中提供了4种处理错误的方法：

- 用 throwing 函数传递错误

- 用 do-catch 语句处理错误

- 使用`try?`将错误作为可选类型处理

- 使用`try!`断言此错误根本不会发生


### 3.1 throwing函数

为了表示一个函数、方法或构造器可以抛出错误，在函数声明的参数之后加上 `throws` 关键字。一个标有 `throws` 关键字的函数被称作 `throwing` 函数。如果这个函数指明了返回值类型，`throws` 关键词需要写在返回箭头（->）的前面。

在`throwing` 函数中，调用了 `throwing` 函数或者抛出了错误，可以不全部处理。错误会传递到调用该`throwing` 函数的代码。

```swift
func canThrowErrors() throws -> String

func cannotThrowErrors() -> String
```

> 只有 throwing 函数可以传递错误。任何在某个非 throwing 函数内部抛出的错误只能在函数内部处理。

### 3.2 用 do-catch 语句处理错误

如果希望直接处理错误而不传递到上一层调用者，可以使用`do-catch`

在 `catch` 后面写一个`匹配模式`来表明这个子句能处理什么样的错误。如果一条 `catch` 子句没有指定匹配模式，那么这条子句**可以匹配任何错误**，并且把错误绑定到一个名字为 `error` 的局部常量。关于模式匹配的更多信息请参考 [模式](https://swiftgg.gitbook.io/swift/yu-yan-can-kao/08_patterns) 。

```swift 
var vendingMachine = VendingMachine()
vendingMachine.coinsDeposited = 8
do {
    try buyFavoriteSnack(person: "Alice", vendingMachine: vendingMachine)
    print("Success! Yum.")
} catch VendingMachineError.invalidSelection {
    print("Invalid Selection.")
} catch VendingMachineError.outOfStock {
    print("Out of Stock.")
} catch VendingMachineError.insufficientFunds(let coinsNeeded) {
    print("Insufficient funds. Please insert an additional \(coinsNeeded) coins.")
} catch {
    print("Unexpected error: \(error).")
}
// 打印“Insufficient funds. Please insert an additional 2 coins.”
```

### 3.3 使用`try?`将错误作为可选类型处理

`try?` 隐式的处理了错误，如果发生了错误则返回`nil`,如果未发生则相当于正常调用


```swift

func someThrowingFunction() throws -> Int {
    // ...
}

let x = try? someThrowingFunction()


// 上面的try? 调用相当与下面的代码

let y: Int?
do {
    y = try someThrowingFunction()
} catch {
    y = nil
}

```

### 3.4 使用`try!`断言此错误根本不会发生

如果调用某个`throwing` 函数，确定不会抛出错误，可以使用 `try!` 简化调用。

如果真的抛出了错误，你会得到一个运行时错误。

```swift
let photo = try! loadImage(atPath: "./Resources/John Appleseed.jpg")
```


## 4. 指定清理操作

你可以使用 `defer` 语句在即将离开当前代码块时执行一系列语句。**该语句让你能执行一些必要的清理工作，不管是以何种方式离开当前代码块的——无论是由于抛出错误而离开，或是由于诸如 return、break 的语句**。

`defer` 语句将代码的执行延迟到当前的作用域退出之前。该语句由 `defer` 关键字和要被延迟执行的语句组成。延迟执行的语句不能包含任何控制转移语句，例如 `break`、`return` 语句，或是抛出一个错误。**延迟执行的操作会按照它们声明的顺序从后往前执行——也就是说，第一条 `defer` 语句中的代码最后才执行，第二条 `defer` 语句中的代码倒数第二个执行，以此类推。最后一条语句会第一个执行**。

```swift
func processFile(filename: String) throws {
    if exists(filename) {
        let file = open(filename)
        defer {
            close(file)
        }
        while let line = try file.readline() {
            // 处理文件。
        }
        // close(file) 会在这里被调用，即作用域的最后。
    }
}
```

> 即使没有涉及到错误处理的代码，你也可以使用 `defer` 语句


## 总结

- 错误处理机制是用来处理可恢复的错误的

- 错误对象可以是类，结构体或者枚举，需要实现`Error`协议

- throws方法将方法内发生的错误抛给上一级调用对象

- do-catch语句用于在当前方法中处理错误；如果不能完全处理，需要将当前方法定义为throws方法

- try? 语句将错误作为可选类型处理，发生错误返回nil

- try! 假定不会发生错误；如果发生了，将得到运行时错误